{
 "cells": [
  {
   "cell_type": "code",
   "execution_count": 1,
   "metadata": {},
   "outputs": [],
   "source": [
    "import tensorflow as tf\n",
    "from tensorflow import keras"
   ]
  },
  {
   "cell_type": "code",
   "execution_count": 2,
   "metadata": {},
   "outputs": [
    {
     "ename": "UnicodeDecodeError",
     "evalue": "'utf-8' codec can't decode byte 0xc1 in position 28: invalid start byte",
     "output_type": "error",
     "traceback": [
      "\u001b[1;31m---------------------------------------------------------------------------\u001b[0m",
      "\u001b[1;31mUnicodeDecodeError\u001b[0m                        Traceback (most recent call last)",
      "Cell \u001b[1;32mIn[2], line 1\u001b[0m\n\u001b[1;32m----> 1\u001b[0m new_model \u001b[39m=\u001b[39m tf\u001b[39m.\u001b[39;49mkeras\u001b[39m.\u001b[39;49mmodels\u001b[39m.\u001b[39;49mload_model(\u001b[39m\"\u001b[39;49m\u001b[39mmodelo_teste_com_erro.h5\u001b[39;49m\u001b[39m\"\u001b[39;49m)\n",
      "File \u001b[1;32mc:\\Users\\mathe\\AppData\\Local\\Programs\\Python\\Python311\\Lib\\site-packages\\keras\\saving\\saving_api.py:212\u001b[0m, in \u001b[0;36mload_model\u001b[1;34m(filepath, custom_objects, compile, safe_mode, **kwargs)\u001b[0m\n\u001b[0;32m    204\u001b[0m     \u001b[39mreturn\u001b[39;00m saving_lib\u001b[39m.\u001b[39mload_model(\n\u001b[0;32m    205\u001b[0m         filepath,\n\u001b[0;32m    206\u001b[0m         custom_objects\u001b[39m=\u001b[39mcustom_objects,\n\u001b[0;32m    207\u001b[0m         \u001b[39mcompile\u001b[39m\u001b[39m=\u001b[39m\u001b[39mcompile\u001b[39m,\n\u001b[0;32m    208\u001b[0m         safe_mode\u001b[39m=\u001b[39msafe_mode,\n\u001b[0;32m    209\u001b[0m     )\n\u001b[0;32m    211\u001b[0m \u001b[39m# Legacy case.\u001b[39;00m\n\u001b[1;32m--> 212\u001b[0m \u001b[39mreturn\u001b[39;00m legacy_sm_saving_lib\u001b[39m.\u001b[39;49mload_model(\n\u001b[0;32m    213\u001b[0m     filepath, custom_objects\u001b[39m=\u001b[39;49mcustom_objects, \u001b[39mcompile\u001b[39;49m\u001b[39m=\u001b[39;49m\u001b[39mcompile\u001b[39;49m, \u001b[39m*\u001b[39;49m\u001b[39m*\u001b[39;49mkwargs\n\u001b[0;32m    214\u001b[0m )\n",
      "File \u001b[1;32mc:\\Users\\mathe\\AppData\\Local\\Programs\\Python\\Python311\\Lib\\site-packages\\keras\\utils\\traceback_utils.py:70\u001b[0m, in \u001b[0;36mfilter_traceback.<locals>.error_handler\u001b[1;34m(*args, **kwargs)\u001b[0m\n\u001b[0;32m     67\u001b[0m     filtered_tb \u001b[39m=\u001b[39m _process_traceback_frames(e\u001b[39m.\u001b[39m__traceback__)\n\u001b[0;32m     68\u001b[0m     \u001b[39m# To get the full stack trace, call:\u001b[39;00m\n\u001b[0;32m     69\u001b[0m     \u001b[39m# `tf.debugging.disable_traceback_filtering()`\u001b[39;00m\n\u001b[1;32m---> 70\u001b[0m     \u001b[39mraise\u001b[39;00m e\u001b[39m.\u001b[39mwith_traceback(filtered_tb) \u001b[39mfrom\u001b[39;00m \u001b[39mNone\u001b[39;00m\n\u001b[0;32m     71\u001b[0m \u001b[39mfinally\u001b[39;00m:\n\u001b[0;32m     72\u001b[0m     \u001b[39mdel\u001b[39;00m filtered_tb\n",
      "File \u001b[1;32mc:\\Users\\mathe\\AppData\\Local\\Programs\\Python\\Python311\\Lib\\site-packages\\tensorflow\\python\\lib\\io\\file_io.py:703\u001b[0m, in \u001b[0;36mis_directory_v2\u001b[1;34m(path)\u001b[0m\n\u001b[0;32m    694\u001b[0m \u001b[39m\u001b[39m\u001b[39m\"\"\"Returns whether the path is a directory or not.\u001b[39;00m\n\u001b[0;32m    695\u001b[0m \n\u001b[0;32m    696\u001b[0m \u001b[39mArgs:\u001b[39;00m\n\u001b[1;32m   (...)\u001b[0m\n\u001b[0;32m    700\u001b[0m \u001b[39m  True, if the path is a directory; False otherwise\u001b[39;00m\n\u001b[0;32m    701\u001b[0m \u001b[39m\"\"\"\u001b[39;00m\n\u001b[0;32m    702\u001b[0m \u001b[39mtry\u001b[39;00m:\n\u001b[1;32m--> 703\u001b[0m   \u001b[39mreturn\u001b[39;00m _pywrap_file_io\u001b[39m.\u001b[39mIsDirectory(compat\u001b[39m.\u001b[39mpath_to_bytes(path))\n\u001b[0;32m    704\u001b[0m \u001b[39mexcept\u001b[39;00m errors\u001b[39m.\u001b[39mOpError:\n\u001b[0;32m    705\u001b[0m   \u001b[39mreturn\u001b[39;00m \u001b[39mFalse\u001b[39;00m\n",
      "\u001b[1;31mUnicodeDecodeError\u001b[0m: 'utf-8' codec can't decode byte 0xc1 in position 28: invalid start byte"
     ]
    }
   ],
   "source": [
    "new_model = tf.keras.models.load_model(\"modelo_teste_com_erro.h5\")"
   ]
  }
 ],
 "metadata": {
  "kernelspec": {
   "display_name": "Python 3",
   "language": "python",
   "name": "python3"
  },
  "language_info": {
   "codemirror_mode": {
    "name": "ipython",
    "version": 3
   },
   "file_extension": ".py",
   "mimetype": "text/x-python",
   "name": "python",
   "nbconvert_exporter": "python",
   "pygments_lexer": "ipython3",
   "version": "3.11.3"
  },
  "orig_nbformat": 4
 },
 "nbformat": 4,
 "nbformat_minor": 2
}
